<?xml version="1.0" ?>
<!-- =================================================================================== -->
<!-- |    This document was autogenerated by xacro from hopejr_arm.urdf.xacro          | -->
<!-- |    EDITING THIS FILE BY HAND IS NOT RECOMMENDED                                 | -->
<!-- =================================================================================== -->
<robot name="hopejr_arm">
  <link name="base_footprint"/>
  <link name="base_link">
    <visual>
      <origin rpy="0.0 0 0" xyz="0 0 0"/>
      <geometry>
        <mesh filename="package://hopejr_arm_description/meshes/visual/base_link.dae" scale="1 1 1"/>
      </geometry>
    </visual>
    <collision>
      <origin rpy="0 0 0" xyz="0 0 0"/>
      <geometry>
        <mesh filename="package://hopejr_arm_description/meshes/collision/base_link.stl" scale="1 1 1"/>
      </geometry>
    </collision>
    <inertial>
      <origin rpy="0 0 0" xyz="-0.02 0 0.028"/>
      <mass value="2.0"/>
      <inertia ixx="0.000213" ixy="0" ixz="0" iyy="0.007034" iyz="0" izz="0.008104"/>
    </inertial>
  </link>
  <joint name="base_link_fixed" type="fixed">
    <parent link="base_footprint"/>
    <child link="base_link"/>
    <origin rpy="0 0 0" xyz="0 0 0"/>
  </joint>
  <link name="shoulder_yaw">
    <visual>
      <origin rpy="0 0 0" xyz="0 0 0"/>
      <geometry>
        <mesh filename="package://hopejr_arm_description/meshes/visual/shoulder_yaw.dae" scale="1 1 1"/>
      </geometry>
    </visual>
    <collision>
      <origin rpy="0 0 0" xyz="0 0 0"/>
      <geometry>
        <mesh filename="package://hopejr_arm_description/meshes/collision/shoulder_yaw.stl" scale="1 1 1"/>
      </geometry>
    </collision>
    <inertial>
      <origin rpy="0 0 0" xyz="0 0 0"/>
      <mass value="2.0"/>
      <inertia ixx="0.01" ixy="0" ixz="0" iyy="0.01" iyz="0" izz="0.01"/>
    </inertial>
  </link>
  <joint name="shoulder_pitch" type="continuous">
    <parent link="base_link"/>
    <child link="shoulder_yaw"/>
    <origin rpy="0 0 0" xyz="0 0.07106 0.04453"/>
    <axis xyz="0 1 0"/>
    <limit effort="10" velocity="1.0"/>
  </joint>
  <link name="shoulder_roll">
    <visual>
      <origin rpy="0 0 0" xyz="0 0 0"/>
      <geometry>
        <mesh filename="package://hopejr_arm_description/meshes/visual/shoulder_roll.dae" scale="1 1 1"/>
      </geometry>
    </visual>
    <collision>
      <origin rpy="0 0 0" xyz="0 0 0"/>
      <geometry>
        <mesh filename="package://hopejr_arm_description/meshes/collision/shoulder_roll.stl" scale="1 1 1"/>
      </geometry>
    </collision>
    <inertial>
      <origin rpy="0 0 0" xyz="-0.02 0 0.028"/>
      <mass value="2.0"/>
      <inertia ixx="0.01" ixy="0" ixz="0" iyy="0.01" iyz="0" izz="0.01"/>
    </inertial>
  </link>
  <joint name="shoulder_yaw" type="revolute">
    <parent link="shoulder_yaw"/>
    <child link="shoulder_roll"/>
    <origin rpy="-1.5707963267948966 0 0" xyz="0 0.05585 0"/>
    <axis xyz="1 0 0"/>
    <limit effort="10" lower="-1.71" upper="1.681" velocity="1.0"/>
  </joint>
  <link name="upper_elbow">
    <visual>
      <origin rpy="0 0 0" xyz="0 0 0"/>
      <geometry>
        <mesh filename="package://hopejr_arm_description/meshes/visual/upper_elbow.dae" scale="1 1 1"/>
      </geometry>
    </visual>
    <collision>
      <origin rpy="0 0 0" xyz="0 0 0"/>
      <geometry>
        <mesh filename="package://hopejr_arm_description/meshes/collision/upper_elbow.stl" scale="1 1 1"/>
      </geometry>
    </collision>
    <inertial>
      <origin rpy="0 0 0" xyz="-0.02 0 0.028"/>
      <mass value="2.0"/>
      <inertia ixx="0.01" ixy="0" ixz="0" iyy="0.01" iyz="0" izz="0.01"/>
    </inertial>
  </link>
  <joint name="shoulder_roll" type="revolute">
    <parent link="shoulder_roll"/>
    <child link="upper_elbow"/>
    <origin rpy="0 0 0" xyz="0 0 0.0884"/>
    <axis xyz="0 0 1"/>
    <limit effort="10" lower="-1.172" upper="1.172" velocity="1.0"/>
  </joint>
  <link name="lower_elbow">
    <visual>
      <origin rpy="0 0 0" xyz="0 0 0"/>
      <geometry>
        <mesh filename="package://hopejr_arm_description/meshes/visual/lower_elbow.dae" scale="1 1 1"/>
      </geometry>
    </visual>
    <collision>
      <origin rpy="0 0 0" xyz="0 0 0"/>
      <geometry>
        <mesh filename="package://hopejr_arm_description/meshes/collision/lower_elbow.stl" scale="1 1 1"/>
      </geometry>
    </collision>
    <inertial>
      <origin rpy="0 0 0" xyz="-0.02 0 0.028"/>
      <mass value="2.0"/>
      <inertia ixx="0.01" ixy="0" ixz="0" iyy="0.01" iyz="0" izz="0.01"/>
    </inertial>
  </link>
  <joint name="elbow_flex" type="revolute">
    <parent link="upper_elbow"/>
    <child link="lower_elbow"/>
    <origin rpy="0 0 0" xyz="0.03765 0 0.11311"/>
    <axis xyz="0 -1 0"/>
    <limit effort="10" lower="-2.53" upper="-0.16" velocity="1.0"/>
  </joint>
  <link name="forearm">
    <visual>
      <origin rpy="0 0 0" xyz="0 0 0"/>
      <geometry>
        <mesh filename="package://hopejr_arm_description/meshes/visual/forearm.dae" scale="1 1 1"/>
      </geometry>
    </visual>
    <collision>
      <origin rpy="0 0 0" xyz="0 0 0"/>
      <geometry>
        <mesh filename="package://hopejr_arm_description/meshes/collision/forearm.stl" scale="1 1 1"/>
      </geometry>
    </collision>
    <inertial>
      <origin rpy="0 0 0" xyz="-0.02 0 0.028"/>
      <mass value="2.0"/>
      <inertia ixx="0.01" ixy="0" ixz="0" iyy="0.01" iyz="0" izz="0.01"/>
    </inertial>
  </link>
  <joint name="wrist_roll" type="revolute">
    <parent link="lower_elbow"/>
    <child link="forearm"/>
    <origin rpy="0 0 0" xyz="0 0 0.06325"/>
    <axis xyz="0 0 -1"/>
    <limit effort="10" lower="-0.7853981633974483" upper="3.665191429188092" velocity="1.0"/>
  </joint>
</robot>
