<?xml version="1.0" ?>
<!-- =================================================================================== -->
<!-- |    This document was autogenerated by xacro from hopejr_arm.urdf.xacro          | -->
<!-- |    EDITING THIS FILE BY HAND IS NOT RECOMMENDED                                 | -->
<!-- =================================================================================== -->
<robot name="hopejr_arm">
  <link name="base_footprint"/>
  <link name="base_link">
    <visual>
      <origin rpy="0.0 0 0" xyz="0 0 0"/>
      <geometry>
        <mesh filename="package://hopejr_arm_description/meshes/visual/base_link.dae" scale="1 1 1"/>
      </geometry>
    </visual>
    <collision>
      <origin rpy="0 0 0" xyz="0 0 0"/>
      <geometry>
        <mesh filename="package://hopejr_arm_description/meshes/collision/base_link.stl" scale="1 1 1"/>
      </geometry>
    </collision>
    <inertial>
      <origin rpy="0 0 0" xyz="-0.02 0 0.028"/>
      <mass value="1.260139"/>
      <inertia ixx="0.003444" ixy="0.000000060725" ixz="0.000000223974" iyy="0.003173" iyz="0.0003306" izz="0.002316"/>
    </inertial>
  </link>
  <joint name="base_link_fixed" type="fixed">
    <parent link="base_footprint"/>
    <child link="base_link"/>
    <origin rpy="0 0 0" xyz="0 0 0"/>
  </joint>
  <link name="shoulder_yaw">
    <visual>
      <origin rpy="0 0 0" xyz="0 0 0"/>
      <geometry>
        <mesh filename="package://hopejr_arm_description/meshes/visual/shoulder_yaw.dae" scale="1 1 1"/>
      </geometry>
    </visual>
    <collision>
      <origin rpy="0 0 0" xyz="0 0 0"/>
      <geometry>
        <mesh filename="package://hopejr_arm_description/meshes/collision/shoulder_yaw.stl" scale="1 1 1"/>
      </geometry>
    </collision>
    <inertial>
      <origin rpy="0 0 0" xyz="0 0 0"/>
      <mass value="0.252213"/>
      <inertia ixx="0.0001227" ixy="0.000000629536" ixz="-0.000000333468" iyy="0.0001678" iyz="-0.000000674054" izz="0.0001553"/>
    </inertial>
  </link>
  <joint name="shoulder_pitch" type="continuous">
    <parent link="base_link"/>
    <child link="shoulder_yaw"/>
    <origin rpy="0 0 0" xyz="0 0.07106 0.04453"/>
    <axis xyz="0 1 0"/>
    <limit effort="10" velocity="1.0"/>
  </joint>
  <link name="shoulder_roll">
    <visual>
      <origin rpy="0 0 0" xyz="0 0 0"/>
      <geometry>
        <mesh filename="package://hopejr_arm_description/meshes/visual/shoulder_roll.dae" scale="1 1 1"/>
      </geometry>
    </visual>
    <collision>
      <origin rpy="0 0 0" xyz="0 0 0"/>
      <geometry>
        <mesh filename="package://hopejr_arm_description/meshes/collision/shoulder_roll.stl" scale="1 1 1"/>
      </geometry>
    </collision>
    <inertial>
      <origin rpy="0 0 0" xyz="-0.02 0 0.028"/>
      <mass value="0.422614"/>
      <inertia ixx="0.0006959" ixy="0.000006134701" ixz="-0.000083430347" iyy="0.0007655" iyz="0.000025066263" izz="0.0002446"/>
    </inertial>
  </link>
  <joint name="shoulder_yaw" type="revolute">
    <parent link="shoulder_yaw"/>
    <child link="shoulder_roll"/>
    <origin rpy="-1.5707963267948966 0 0" xyz="0 0.05585 0"/>
    <axis xyz="1 0 0"/>
    <limit effort="10" lower="-1.71" upper="1.681" velocity="1.0"/>
  </joint>
  <link name="upper_elbow">
    <visual>
      <origin rpy="0 0 0" xyz="0 0 0"/>
      <geometry>
        <mesh filename="package://hopejr_arm_description/meshes/visual/upper_elbow.dae" scale="1 1 1"/>
      </geometry>
    </visual>
    <collision>
      <origin rpy="0 0 0" xyz="0 0 0"/>
      <geometry>
        <mesh filename="package://hopejr_arm_description/meshes/collision/upper_elbow.stl" scale="1 1 1"/>
      </geometry>
    </collision>
    <inertial>
      <origin rpy="0 0 0" xyz="-0.02 0 0.028"/>
      <mass value="0.243803"/>
      <inertia ixx="0.0003227" ixy="-0.000000062111" ixz="-0.0001214" iyy="0.0003959" iyz="-0.000000048168" izz="0.0001746"/>
    </inertial>
  </link>
  <joint name="shoulder_roll" type="revolute">
    <parent link="shoulder_roll"/>
    <child link="upper_elbow"/>
    <origin rpy="0 0 0" xyz="0 0 0.0884"/>
    <axis xyz="0 0 1"/>
    <limit effort="10" lower="-1.172" upper="1.172" velocity="1.0"/>
  </joint>
  <link name="lower_elbow">
    <visual>
      <origin rpy="0 0 0" xyz="0 0 0"/>
      <geometry>
        <mesh filename="package://hopejr_arm_description/meshes/visual/lower_elbow.dae" scale="1 1 1"/>
      </geometry>
    </visual>
    <collision>
      <origin rpy="0 0 0" xyz="0 0 0"/>
      <geometry>
        <mesh filename="package://hopejr_arm_description/meshes/collision/lower_elbow.stl" scale="1 1 1"/>
      </geometry>
    </collision>
    <inertial>
      <origin rpy="0 0 0" xyz="-0.02 0 0.028"/>
      <mass value="0.1882"/>
      <inertia ixx="0.0001196" ixy="0.000002288885" ixz="0.000001137302" iyy="0.000096307138" iyz="0.000003223544" izz="0.0001047"/>
    </inertial>
  </link>
  <joint name="elbow_flex" type="revolute">
    <parent link="upper_elbow"/>
    <child link="lower_elbow"/>
    <origin rpy="0 0 0" xyz="0.03765 0 0.11311"/>
    <axis xyz="0 -1 0"/>
    <limit effort="10" lower="-2.53" upper="-0.16" velocity="1.0"/>
  </joint>
  <link name="forearm">
    <visual>
      <origin rpy="0 0 0" xyz="0 0 0"/>
      <geometry>
        <mesh filename="package://hopejr_arm_description/meshes/visual/forearm.dae" scale="1 1 1"/>
      </geometry>
    </visual>
    <collision>
      <origin rpy="0 0 0" xyz="0 0 0"/>
      <geometry>
        <mesh filename="package://hopejr_arm_description/meshes/collision/forearm.stl" scale="1 1 1"/>
      </geometry>
    </collision>
    <inertial>
      <origin rpy="0 0 0" xyz="-0.02 0 0.028"/>
      <mass value="0.208355"/>
      <inertia ixx="0.0002051" ixy="0.000000044894" ixz="-0.000004226706" iyy="0.0002222" iyz="-0.000002431512" izz="0.0001122"/>
    </inertial>
  </link>
  <joint name="wrist_roll" type="revolute">
    <parent link="lower_elbow"/>
    <child link="forearm"/>
    <origin rpy="0 0 0" xyz="0 0 0.06325"/>
    <axis xyz="0 0 -1"/>
    <limit effort="10" lower="-0.7853981633974483" upper="3.665191429188092" velocity="1.0"/>
  </joint>
</robot>
